<mujoco model="MuJoCo Model">
  <compiler angle="radian"/>

  <visual>
    <global offwidth="2048" offheight="1536"/>
    <quality shadowsize="8192"/>
    <headlight diffuse="0.5 0.5 0.5" specular="1 1 1"/>
  </visual>

  <default>
    <default class="main-rodent">
      <joint solreflimit="0.01" solimplimit="0.9 0.99 0.003" limited="true" armature="6e-07" damping="0.001"/>
      <geom friction="0.7" solref="0.005"/>
      <site group="3" rgba="0 0 1 1"/>

      <tendon limited="false"/>
      <general ctrllimited="true" ctrlrange="-1 1" forcelimited="false" gainprm="0.01"/>
      <default class="bone-rodent">
        <geom contype="0" conaffinity="0" density="1100"/>
      </default>
      <default class="no_collision-rodent">
        <geom type="capsule" contype="0" conaffinity="0" group="2"/>
      </default>
      <default class="collision-rodent">
        <geom condim="1" group="2"/>
        <default class="nonself_collision_primitive-rodent">
          <geom type="capsule" conaffinity="0" density="500" rgba="0 0.5 0.5 1"/>
          <default class="nonself_collision_primitive_paw-rodent">
            <geom condim="3" priority="1" friction="1.5" rgba="0 0.6 0.7 1"/>
          </default>
        </default>
      </default>
      <default class="lumbar-rodent">
        <joint group="3" armature="1e-05" damping="0.03"/>
        <general gainprm="0.15"/>
        <default class="lumbar_extend-rodent">
          <joint stiffness="0.02" range="-0.523599 0.785398"/>

          <tendon range="-1 1"/>
          <general gainprm="0.4"/>
        </default>
        <default class="lumbar_bend-rodent">
          <joint stiffness="0.03" range="-0.523599 0.523599"/>

          <tendon range="-1 1"/>
        </default>
        <default class="lumbar_twist-rodent">
          <joint stiffness="0.03" range="-0.523599 0.523599"/>

          <tendon range="-1 1"/>
        </default>
      </default>
      <default class="cervical-rodent">
        <joint group="3" stiffness="1" armature="0.001" damping="1"/>
        <default class="cervical_extend-rodent">
          <joint range="-0.407243 0.610865"/>

          <tendon range="-1 1"/>
          <general gainprm="2.5"/>
        </default>
        <default class="cervical_bend-rodent">
          <joint range="-0.610865 0.610865"/>

          <tendon range="-1 1"/>
          <general gainprm="2.5"/>
        </default>
        <default class="cervical_twist-rodent">
          <joint range="-0.610865 0.610865"/>

          <tendon range="-1 1"/>
          <general gainprm="2.5"/>
        </default>
      </default>
      <default class="atlas-rodent">
        <joint stiffness="0.002" range="-0.0872665 0.785398" damping="0.002"/>
        <general gainprm="0.025"/>
      </default>
      <default class="mandible-rodent">
        <joint springref="-0.314159" stiffness="0.002" range="-0.296706 0.261799" damping="0.002"/>
        <general gainprm="0.025"/>
      </default>
      <default class="caudal-rodent">
        <joint group="3" stiffness="1e-05" damping="0.002"/>
        <general gainprm="0.005"/>
        <default class="caudal_extend-rodent">
          <joint range="-0.0872665 0.0872665"/>

          <tendon range="-0.05 0.05"/>
        </default>
        <default class="caudal_bend-rodent">
          <joint range="-0.0872665 0.0872665"/>

          <tendon range="-0.2 0.2"/>
        </default>
      </default>
      <default class="hip-rodent">
        <joint armature="1e-05" damping="0.02"/>
        <general gainprm="0.2"/>
        <default class="hip_supinate-rodent">
          <joint range="-0.698132 0.523599"/>
        </default>
        <default class="hip_abduct-rodent">
          <joint range="-0.523599 1.0472"/>
        </default>
        <default class="hip_extend-rodent">
          <joint range="-1.5708 1.0472"/>
          <general gainprm="0.3"/>
        </default>
      </default>
      <default class="knee-rodent">
        <joint range="-1.22173 1.53589" damping="0.005"/>
        <general gainprm="0.2"/>
      </default>
      <default class="ankle-rodent">
        <joint range="-0.1 2.0" damping="0.003"/>
        <general gainprm="0.2"/>
      </default>
      <default class="toe-rodent">
        <joint range="-0.7 0.87"/>
        <general gainprm="0.025"/>
      </default>
      <default class="scapula-rodent">
        <joint damping="0.005"/>
        <general gainprm="0.25"/>
        <default class="scapula_supinate-rodent">
          <joint range="-0.0174533 0.174533"/>
        </default>
        <default class="scapula_abduct-rodent">
          <joint range="-0.261799 0.261799"/>
        </default>
        <default class="scapula_extend-rodent">
          <joint range="-0.0349066 0.0349066"/>
        </default>
      </default>
      <default class="shoulder-rodent">
        <joint range="-1.309 0.872665" damping="0.005"/>
        <general gainprm="0.15"/>
      </default>
      <default class="shoulder_sup-rodent">
        <joint range="-0.0523599 1.13446" damping="0.005"/>
        <general gainprm="0.15"/>
      </default>
      <default class="elbow-rodent">
        <joint range="-1.309 0.698132" damping="0.003"/>
        <general gainprm="0.15"/>
      </default>
      <default class="wrist-rodent">
        <joint range="-0.349066 2.0944" damping="0.002"/>
        <general gainprm="0.05"/>
      </default>
      <default class="finger-rodent">
        <joint range="0 1.5708" damping="0.002"/>
        <general gainprm="0.025"/>
      </default>
      <default class="sensor-rodent">
        <site group="4"/>
      </default>
    </default>
  </default>

  <asset>
    <texture type="2d" colorspace="auto" name="grid" builtin="checker" rgb1="0.1 0.2 0.3" rgb2="0.2 0.3 0.4" width="512" height="512"/>
    <texture type="2d" colorspace="auto" name="grid-rodent" builtin="checker" rgb1="0.1 0.2 0.3" rgb2="0.2 0.3 0.4" width="512" height="512"/>
    <material name="grid" texture="grid" texuniform="true" reflectance="0.2"/>
    <material name="grid-rodent" texture="grid-rodent" texuniform="true" reflectance="0.2"/>
    <skin name="skin" file="rodent_walker_skin.skn"/>
  </asset>

  <worldbody>
    <body name="floor">
      <geom name="floor" size="10 10 0.005" pos="0 0 -0.005" type="plane" contype="0" material="grid"/>
    </body>
    <body name="walker-rodent">
      <joint name="root" type="free"/>
      <body name="torso-rodent" pos="0.0278957 1.85267e-07 0.0585806">
        <geom name="collision_torso-rodent" class="no_collision-rodent" size="0.045 0.0216 0.0234" pos="-0.00738 0 0" quat="0.996195 0 0.0871557 0" type="ellipsoid" density="468.251"/>
        <camera name="close_profile-rodent" pos="0.5 -0.5 0.5" quat="0.820473 0.424708 0.17592 0.339851" mode="trackcom"/>
        <camera name="back-rodent" pos="-1 0 0.5" quat="0.601501 0.371748 -0.371748 -0.601501" mode="trackcom"/>
        <camera name="side-rodent" pos="0 -1 0.5" quat="0.850651 0.525731 0 0" mode="trackcom"/>
        <camera name="side_alt-rodent" pos="0.5 -0.561 0.199" quat="0.743222 0.574963 0.209332 0.270591" mode="trackcom"/>
        <camera name="top-rodent" pos="0 0 1" quat="0.995133 0.0985376 0 0" mode="trackcom" fovy="100"/>
        <light name="tracking_light-rodent" pos="0 0 3" dir="0 0 -1" mode="trackcom"/>
        <body name="vertebra_1-rodent" pos="-0.0172615 -1.6923e-07 0.0151618">
          <joint name="vertebra_1_extend-rodent" class="lumbar_extend-rodent" pos="0.003 0 -0.003" axis="0 1 0"/>
          <geom name="vertebra_1_collision-rodent" class="no_collision-rodent" size="0.009" pos="0 0 -0.001476" type="sphere"/>
          <body name="vertebra_2-rodent" pos="-0.00506674 2.33532e-06 0.000478883">
            <joint name="vertebra_2_bend-rodent" class="lumbar_bend-rodent" pos="0.003 0 -0.003" axis="0 0 1"/>
            <geom name="vertebra_2_collision-rodent" class="no_collision-rodent" size="0.009" pos="0 0 -0.001476" type="sphere"/>
            <body name="vertebra_3-rodent" pos="-0.00586545 -9.36957e-06 -8.5205e-05">
              <joint name="vertebra_3_twist-rodent" class="lumbar_twist-rodent" pos="0.003 0 -0.003" axis="1 0 0"/>
              <geom name="vertebra_3_collision-rodent" class="no_collision-rodent" size="0.009" pos="0 0 -0.001476" type="sphere"/>
              <body name="vertebra_4-rodent" pos="-0.00609993 7.87149e-06 -0.00116938">
                <joint name="vertebra_4_extend-rodent" class="lumbar_extend-rodent" pos="0.003 0 -0.003" axis="0 1 0"/>
                <geom name="vertebra_4_collision-rodent" class="no_collision-rodent" size="0.009" pos="0 0 -0.001476" type="sphere"/>
                <body name="vertebra_5-rodent" pos="-0.00620106 -5.5839e-06 -0.00224826">
                  <joint name="vertebra_5_bend-rodent" class="lumbar_bend-rodent" pos="0.003 0 -0.003" axis="0 0 1"/>
                  <geom name="vertebra_5_collision-rodent" class="no_collision-rodent" size="0.009" pos="0 0 -0.001476" type="sphere"/>
                  <body name="vertebra_6-rodent" pos="-0.00556676 4.729e-06 -0.00327701">
                    <joint name="vertebra_6_twist-rodent" class="lumbar_twist-rodent" pos="0.003 0 -0.003" axis="1 0 0"/>
                    <geom name="vertebra_6_collision-rodent" class="no_collision-rodent" size="0.009" pos="0 0 -0.001476" type="sphere"/>
                    <body name="pelvis-rodent" pos="-0.0117643 3.1619e-06 -0.00730888">
                      <geom name="collision_pelvis_L-rodent" class="no_collision-rodent" size="0.0117 0.0189" pos="-0.000738 0.005904 -0.005166" quat="0.906308 0 0.422618 0" density="1548.58"/>
                      <geom name="collision_pelvis_R-rodent" class="no_collision-rodent" size="0.0117 0.0189" pos="-0.000738 -0.005904 -0.005166" quat="0.906308 0 0.422618 0" density="1548.58"/>
                      <geom name="collision_pelvis_gut-rodent" class="no_collision-rodent" size="0.018 0.018 0.0162" pos="0.01845 0 -0.01476" quat="0.965926 0 -0.258819 0" type="ellipsoid" density="1548.58"/>
                      <site name="hip_L-rodent" pos="-0.00481029 0.0114913 -0.00988782" size="0.0022" group="3" rgba="0 0 1 1"/>
                      <site name="hip_R-rodent" pos="-0.00481029 -0.0114913 -0.00988782" size="0.0022" group="3" rgba="0 0 1 1"/>
                      <body name="upper_leg_L-rodent" pos="-0.00432926 0.0103421 -0.00889904">
                        <joint name="hip_L_supinate-rodent" class="hip_supinate-rodent" pos="0 0 0" axis="0 0 1"/>
                        <joint name="hip_L_abduct-rodent" class="hip_abduct-rodent" pos="0 0 0" axis="1 0 0"/>
                        <joint name="hip_L_extend-rodent" class="hip_extend-rodent" pos="0 0 0" axis="0 1 0"/>
                        <geom name="upper_leg_L0_collision-rodent" class="no_collision-rodent" size="0.00786816 0.0157363" pos="0.00774227 0.00967784 -0.0116134" quat="0.896201 0.282571 -0.32619 -0.102847" density="1561.76"/>
                        <site name="knee_L-rodent" pos="0.0154226 0.017479 -0.0257044" quat="0.707107 -0.707107 0 0" size="0.0006 0.004" group="3" type="cylinder" rgba="0 0 1 1"/>
                        <body name="lower_leg_L-rodent" pos="0.0138804 0.0157311 -0.023134">
                          <joint name="knee_L-rodent" class="knee-rodent" pos="0 0 0" axis="0.447214 -0.894427 0"/>
                          <geom name="lower_leg_L_collision-rodent" class="no_collision-rodent" size="0.00590112 0.01731" pos="-0.0110371 0.000110231 -0.00964632" quat="0.584394 0.278582 0.390045 0.654783" density="1302.87"/>
                          <site name="ankle_L-rodent" pos="-0.0323015 -0.00472705 -0.0220596" quat="0.707107 -0.707107 0 0" size="0.0006 0.0026" group="3" type="cylinder" rgba="0 0 1 1"/>
                          <body name="foot_L-rodent" pos="-0.0290714 -0.00425435 -0.0198536">
                            <joint name="ankle_L-rodent" class="ankle-rodent" pos="0 0 0" axis="-0.287348 0.957826 0"/>
                            <geom name="foot_L_collision-rodent" class="nonself_collision_primitive_paw-rodent" size="0.00288964 0.0111458" pos="0.00744702 0.002031 -0.002031" quat="0.579228 0.579228 -0.40558 -0.40558" density="2041.16"/>
                            <site name="toe_L-rodent" pos="0.0210999 0.00761433 -0.00275217" quat="0.707107 -0.707107 0 0" size="0.0006 0.005" group="3" type="cylinder" rgba="0 0 1 1"/>
                            <body name="toe_L-rodent" pos="0.0189899 0.00685289 -0.00247695">
                              <joint name="toe_L-rodent" class="toe-rodent" pos="0 0 0" axis="0 1 0"/>
                              <geom name="toe_L0_collision-rodent" class="nonself_collision_primitive_paw-rodent" size="0.00214489 0.00652792" pos="0.00764699 -0.000764699 0" quat="0.579228 0.579228 -0.40558 -0.40558"/>
                              <geom name="toe_L1_collision-rodent" class="nonself_collision_primitive_paw-rodent" size="0.00214489 0.0069942" pos="0.00726464 0.0022941 0" quat="0.579228 0.579228 -0.40558 -0.40558"/>
                              <geom name="toe_L2_collision-rodent" class="nonself_collision_primitive_paw-rodent" size="0.00214489 0.00652792" pos="0.00611759 0.00497054 0" quat="0.579228 0.579228 -0.40558 -0.40558"/>
                              <site name="sole_L-rodent" class="sensor-rodent" pos="0.0082 0.00246 -0.00164" quat="0.984808 0 0 0.173648" size="0.006 0.004 0.002" type="box"/>
                            </body>
                          </body>
                        </body>
                      </body>
                      <body name="upper_leg_R-rodent" pos="-0.00432926 -0.0103421 -0.00889904">
                        <joint name="hip_R_supinate-rodent" class="hip_supinate-rodent" pos="0 0 0" axis="0 0 -1"/>
                        <joint name="hip_R_abduct-rodent" class="hip_abduct-rodent" pos="0 0 0" axis="-1 0 0"/>
                        <joint name="hip_R_extend-rodent" class="hip_extend-rodent" pos="0 0 0" axis="0 1 0"/>
                        <geom name="upper_leg_R0_collision-rodent" class="no_collision-rodent" size="0.00786816 0.0157363" pos="0.00774227 -0.00967784 -0.0116134" quat="0.896201 -0.282571 -0.32619 0.102847" density="1561.76"/>
                        <site name="knee_R-rodent" pos="0.0154226 -0.017479 -0.0257044" quat="0.707107 -0.707107 0 0" size="0.0006 0.004" group="3" type="cylinder" rgba="0 0 1 1"/>
                        <body name="lower_leg_R-rodent" pos="0.0138804 -0.0157311 -0.023134">
                          <joint name="knee_R-rodent" class="knee-rodent" pos="0 0 0" axis="-0.447214 -0.894427 0"/>
                          <geom name="lower_leg_R_collision-rodent" class="no_collision-rodent" size="0.00590112 0.01731" pos="-0.0108261 -0.000145421 -0.00951672" quat="0.656432 0.390142 0.277958 0.582775" density="1302.87"/>
                          <site name="ankle_R-rodent" pos="-0.0323015 0.00472705 -0.0220596" quat="0.707107 -0.707107 0 0" size="0.0006 0.0026" group="3" type="cylinder" rgba="0 0 1 1"/>
                          <body name="foot_R-rodent" pos="-0.0290714 0.00425435 -0.0198536">
                            <joint name="ankle_R-rodent" class="ankle-rodent" pos="0 0 0" axis="0.287348 0.957826 0"/>
                            <geom name="foot_R_collision-rodent" class="nonself_collision_primitive_paw-rodent" size="0.00288964 0.0111458" pos="0.00744702 -0.002031 -0.002031" quat="0.579228 0.579228 0.40558 0.40558" density="2041.16"/>
                            <site name="toe_R-rodent" pos="0.0210999 -0.00761433 -0.00275217" quat="0.707107 -0.707107 0 0" size="0.0006 0.005" group="3" type="cylinder" rgba="0 0 1 1"/>
                            <body name="toe_R-rodent" pos="0.0189899 -0.00685289 -0.00247695">
                              <joint name="toe_R-rodent" class="toe-rodent" pos="0 0 0" axis="0 1 0"/>
                              <geom name="toe_R0_collision-rodent" class="nonself_collision_primitive_paw-rodent" size="0.00214489 0.00652792" pos="0.00764699 0.000764699 0" quat="0.579228 0.579228 0.40558 0.40558"/>
                              <geom name="toe_R1_collision-rodent" class="nonself_collision_primitive_paw-rodent" size="0.00214489 0.0069942" pos="0.00726464 -0.0022941 0" quat="0.579228 0.579228 0.40558 0.40558"/>
                              <geom name="toe_R2_collision-rodent" class="nonself_collision_primitive_paw-rodent" size="0.00214489 0.00652792" pos="0.00611759 -0.00497054 0" quat="0.579228 0.579228 0.40558 0.40558"/>
                              <site name="sole_R-rodent" class="sensor-rodent" pos="0.0082 -0.00246 -0.00164" quat="0.984808 0 0 -0.173648" size="0.006 0.004 0.002" type="box"/>
                            </body>
                          </body>
                        </body>
                      </body>
                      <body name="vertebra_C1-rodent" pos="-0.0142109 0 -0.0106935">
                        <joint name="vertebra_C1_extend-rodent" class="caudal_extend-rodent" pos="0.00434232 0 0.00326752" axis="0 1 0" range="-0.261799 0.261799"/>
                        <joint name="vertebra_C1_bend-rodent" class="caudal_bend-rodent" pos="0.00434232 0 0.00326752" axis="0.601268 0 -0.799047" range="-0.261799 0.261799"/>
                        <geom name="vertebra_C1_collision-rodent" class="no_collision-rodent" size="0.00986849 0.00213338" quat="0.577241 0.350661 0.324028 0.662447" density="507.157"/>
                        <body name="vertebra_C2-rodent" pos="-0.00348935 0 -0.00380379">
                          <joint name="vertebra_C2_extend-rodent" class="caudal_extend-rodent" pos="0.00355853 0 0.0038792" axis="0 1 0" range="-0.261799 0.261799"/>
                          <joint name="vertebra_C2_bend-rodent" class="caudal_bend-rodent" pos="0.00355853 0 0.0038792" axis="0.736909 0 -0.675992" range="-0.261799 0.261799"/>
                          <geom name="vertebra_C2_collision-rodent" class="no_collision-rodent" size="0.00752433 0.00315554" quat="0.616595 0.346138 0.346138 0.616595" density="507.157"/>
                          <body name="vertebra_C3-rodent" pos="-0.00308162 0 -0.00383677">
                            <joint name="vertebra_C3_extend-rodent" class="caudal_extend-rodent" pos="0.00281463 0 0.00350435" axis="0 1 0" range="-0.261799 0.261799"/>
                            <joint name="vertebra_C3_bend-rodent" class="caudal_bend-rodent" pos="0.00281463 0 0.00350435" axis="0.779657 0 -0.626207" range="-0.261799 0.261799"/>
                            <geom name="vertebra_C3_collision-rodent" class="no_collision-rodent" size="0.00710638 0.0036877" quat="0.658413 0.25786 0.25786 0.658413" density="507.157"/>
                            <body name="vertebra_C4-rodent" pos="-0.00294469 0 -0.00397515">
                              <joint name="vertebra_C4_extend-rodent" class="caudal_extend-rodent" pos="0.00253605 0 0.00342352" axis="0 1 0" range="-0.261799 0.261799"/>
                              <joint name="vertebra_C4_bend-rodent" class="caudal_bend-rodent" pos="0.00253605 0 0.00342352" axis="0.803545 0 -0.595244" range="-0.261799 0.261799"/>
                              <geom name="vertebra_C4_collision-rodent" class="no_collision-rodent" size="0.00598754 0.00346653" quat="0.669896 0.22636 0.22636 0.669896" density="507.157"/>
                              <body name="vertebra_C5-rodent" pos="-0.00285838 0 -0.00411241">
                                <joint name="vertebra_C5_extend-rodent" class="caudal_extend-rodent" pos="0.00201225 0 0.00289506" axis="0 1 0" range="-0.261799 0.261799"/>
                                <joint name="vertebra_C5_bend-rodent" class="caudal_bend-rodent" pos="0.00201225 0 0.00289506" axis="0.821132 0 -0.570738" range="-0.261799 0.261799"/>
                                <geom name="vertebra_C5_collision-rodent" class="no_collision-rodent" size="0.0040908 0.00339897" quat="0.959555 0 0.281521 0" density="507.157"/>
                                <body name="vertebra_C6-rodent" pos="-0.00280727 0 -0.00441122">
                                  <joint name="vertebra_C6_extend-rodent" class="caudal_extend-rodent" pos="0.00210335 0 0.00330511" axis="0 1 0" range="-0.261799 0.261799"/>
                                  <joint name="vertebra_C6_bend-rodent" class="caudal_bend-rodent" pos="0.00210335 0 0.00330511" axis="0.84365 0 -0.536894" range="-0.261799 0.261799"/>
                                  <geom name="vertebra_C6_collision-rodent" class="no_collision-rodent" size="0.00346422 0.00399761" quat="-0.968472 -0.0201654 -0.233836 0.0835185" density="507.157"/>
                                  <body name="vertebra_C7-rodent" pos="-0.00289423 0 -0.00507993">
                                    <joint name="vertebra_C7_extend-rodent" class="caudal_extend-rodent" pos="0.00269018 0 0.00472179" axis="0 1 0" range="-0.261799 0.261799"/>
                                    <geom name="vertebra_C7_collision-rodent" class="no_collision-rodent" size="0.00293125 0.00417501" quat="-0.958718 -0.0286439 -0.262926 0.104445" density="507.157"/>
                                    <body name="vertebra_C8-rodent" pos="-0.00310127 0 -0.00496636">
                                      <geom name="vertebra_C8_collision-rodent" class="no_collision-rodent" size="0.00271424 0.00356133" quat="0.955756 0 0.29416 0" density="507.157"/>
                                      <body name="vertebra_C9-rodent" pos="-0.00385666 0 -0.00460352">
                                        <joint name="vertebra_C9_bend-rodent" class="caudal_bend-rodent" pos="0.00288646 0 0.00344543" axis="0.766549 0 -0.642186" range="-0.261799 0.261799"/>
                                        <geom name="vertebra_C9_collision-rodent" class="no_collision-rodent" size="0.00281753 0.00404541" quat="0.933936 0 0.357439 0" density="507.157"/>
                                        <body name="vertebra_C10-rodent" pos="-0.00437539 0 -0.00410597">
                                          <geom name="vertebra_C10_collision-rodent" class="no_collision-rodent" size="0.00307908 0.0046771" quat="0 0.404822 0 0.914395" density="507.157"/>
                                          <body name="vertebra_C11-rodent" pos="-0.00483731 0 -0.00392779">
                                            <joint name="vertebra_C11_extend-rodent" class="caudal_extend-rodent" pos="0.00273704 0 0.00222242" axis="0 1 0" range="-0.261799 0.261799"/>
                                            <geom name="vertebra_C11_collision-rodent" class="no_collision-rodent" size="0.00224969 0.00350725" quat="0 0.434944 0 0.900457" density="507.157"/>
                                            <body name="vertebra_C12-rodent" pos="-0.00552103 0 -0.00345735">
                                              <geom name="vertebra_C12_collision-rodent" class="no_collision-rodent" size="0.00219019 0.00373156" quat="0 0.508079 0 0.86131" density="507.157"/>
                                              <body name="vertebra_C13-rodent" pos="-0.00620768 0 -0.00233319">
                                                <joint name="vertebra_C13_bend-rodent" class="caudal_bend-rodent" pos="0.00351224 0 0.00132009" axis="0.351824 0 -0.936066" range="-0.261799 0.261799"/>
                                                <geom name="vertebra_C13_collision-rodent" class="no_collision-rodent" size="0.00188164 0.00356398" quat="0 0.629393 0 0.777087" density="507.157"/>
                                                <body name="vertebra_C14-rodent" pos="-0.00614253 0 -0.00081801">
                                                  <geom name="vertebra_C14_collision-rodent" class="no_collision-rodent" size="0.00166055 0.00349066" quat="0 0.686611 0 0.727025" density="507.157"/>
                                                  <body name="vertebra_C15-rodent" pos="-0.00587359 0 -0.000283798">
                                                    <joint name="vertebra_C15_extend-rodent" class="caudal_extend-rodent" pos="0.00393283 0 0.000190025" axis="0 1 0" range="-0.261799 0.261799"/>
                                                    <geom name="vertebra_C15_collision-rodent" class="no_collision-rodent" size="0.00166081 0.00372336" quat="0 0.699185 0 0.714941" density="507.157"/>
                                                    <body name="vertebra_C16-rodent" pos="-0.00602452 0 -0.00012464">
                                                      <geom name="vertebra_C16_collision-rodent" class="no_collision-rodent" size="0.0016903 0.00395608" quat="0 0.707107 0 0.707107" density="507.157"/>
                                                      <body name="vertebra_C17-rodent" pos="-0.00583688 0 -1.50342e-05">
                                                        <joint name="vertebra_C17_bend-rodent" class="caudal_bend-rodent" pos="0.00427941 0 1.10226e-05" axis="0.00257572 0 -0.999997" range="-0.261799 0.261799"/>
                                                        <geom name="vertebra_C17_collision-rodent" class="no_collision-rodent" size="0.00147056 0.00418879" quat="0 0.707107 0 0.707107" density="507.157"/>
                                                        <body name="vertebra_C18-rodent" pos="-0.00558669 0 1.64302e-10">
                                                          <geom name="vertebra_C18_collision-rodent" class="no_collision-rodent" size="0.00147056 0.0044215" quat="0 0.707107 0 0.707107" density="507.157"/>
                                                          <body name="vertebra_C19-rodent" pos="-0.00558383 0 -7.38171e-10">
                                                            <joint name="vertebra_C19_extend-rodent" class="caudal_extend-rodent" pos="0.00427857 0 5.65617e-10" axis="0 1 0" range="-0.261799 0.261799"/>
                                                            <geom name="vertebra_C19_collision-rodent" class="no_collision-rodent" size="0.00147056 0.00465424" quat="0 0.707107 0 0.707107" density="507.157"/>
                                                            <body name="vertebra_C20-rodent" pos="-0.00560554 0 2.26487e-06">
                                                              <geom name="vertebra_C20_collision-rodent" class="no_collision-rodent" size="0.00134846 0.00465888" quat="0 0.707107 0 0.707107" density="507.157"/>
                                                              <body name="vertebra_C21-rodent" pos="-0.00550589 0 -9.86978e-05">
                                                                <joint name="vertebra_C21_bend-rodent" class="caudal_bend-rodent" pos="0.00386316 0 6.92504e-05" axis="0.017923 0 -0.999839" range="-0.261799 0.261799"/>
                                                                <geom name="vertebra_C21_collision-rodent" class="no_collision-rodent" size="0.00137746 0.00447492" quat="0 0.707107 0 0.707107" density="507.157"/>
                                                                <body name="vertebra_C22-rodent" pos="-0.0058573 0 -1.18079e-05">
                                                                  <geom name="vertebra_C22_collision-rodent" class="no_collision-rodent" size="0.00124164 0.00411496" quat="0 0.707107 0 0.707107" density="507.157"/>
                                                                  <body name="vertebra_C23-rodent" pos="-0.00575168 0 1.57626e-09">
                                                                    <joint name="vertebra_C23_extend-rodent" class="caudal_extend-rodent" pos="0.00359622 0 -9.85552e-10" axis="0 1 0" range="-0.261799 0.261799"/>
                                                                    <geom name="vertebra_C23_collision-rodent" class="no_collision-rodent" size="0.00124164 0.00429388" quat="0 0.707107 0 0.707107" density="507.157"/>
                                                                    <body name="vertebra_C24-rodent" pos="-0.00556264 0 -1.12242e-09">
                                                                      <geom name="vertebra_C24_collision-rodent" class="no_collision-rodent" size="0.00124164 0.0044728" quat="0 0.707107 0 0.707107" density="507.157"/>
                                                                      <body name="vertebra_C25-rodent" pos="-0.00537138 0 1.24154e-10">
                                                                        <joint name="vertebra_C25_bend-rodent" class="caudal_bend-rodent" pos="0.00359624 0 -8.31235e-11" axis="-2.3114e-08 0 -1" range="-0.261799 0.261799"/>
                                                                        <geom name="vertebra_C25_collision-rodent" class="no_collision-rodent" size="0.00124164 0.00465173" quat="0 0.707107 0 0.707107" density="507.157"/>
                                                                        <body name="vertebra_C26-rodent" pos="-0.00506581 0 -1.22907e-09">
                                                                          <geom name="vertebra_C26_collision-rodent" class="no_collision-rodent" size="0.00124164 0.0048306" quat="0 0.707107 0 0.707107" density="507.157"/>
                                                                          <body name="vertebra_C27-rodent" pos="-0.00467381 0 1.25612e-09">
                                                                            <joint name="vertebra_C27_extend-rodent" class="caudal_extend-rodent" pos="0.00385382 0 -1.03574e-09" axis="0 1 0" range="-0.261799 0.261799"/>
                                                                            <geom name="vertebra_C27_collision-rodent" class="no_collision-rodent" size="0.00124164 0.00500956" quat="0 0.707107 0 0.707107" density="507.157"/>
                                                                            <body name="vertebra_C28-rodent" pos="-0.00453262 0 4.56658e-07">
                                                                              <geom name="vertebra_C28_collision-rodent" class="no_collision-rodent" size="0.00116715 0.00518843" quat="0 0.707107 0 0.707107" density="507.157"/>
                                                                              <body name="vertebra_C29-rodent" pos="-0.00429651 0 -5.585e-11">
                                                                                <joint name="vertebra_C29_bend-rodent" class="caudal_bend-rodent" pos="0.00374078 0 4.86261e-11" axis="1.29989e-08 0 -1" range="-0.261799 0.261799"/>
                                                                                <geom name="vertebra_C29_collision-rodent" class="no_collision-rodent" size="0.00116715 0.0053674" quat="0 0.707107 0 0.707107" density="507.157"/>
                                                                                <body name="vertebra_C30-rodent" pos="-0.00360482 0 -3.77746e-07">
                                                                                  <geom name="vertebra_C30_collision-rodent" class="no_collision-rodent" size="0.00116807 0.00554627" quat="0 0.707107 0 0.707107" density="507.157"/>
                                                                                </body>
                                                                              </body>
                                                                            </body>
                                                                          </body>
                                                                        </body>
                                                                      </body>
                                                                    </body>
                                                                  </body>
                                                                </body>
                                                              </body>
                                                            </body>
                                                          </body>
                                                        </body>
                                                      </body>
                                                    </body>
                                                  </body>
                                                </body>
                                              </body>
                                            </body>
                                          </body>
                                        </body>
                                      </body>
                                    </body>
                                  </body>
                                </body>
                              </body>
                            </body>
                          </body>
                        </body>
                      </body>
                    </body>
                  </body>
                </body>
              </body>
            </body>
          </body>
        </body>
        <body name="vertebra_cervical_5-rodent" pos="0.0249382 1.06435e-05 -0.000900283">
          <joint name="vertebra_cervical_5_extend-rodent" class="cervical_extend-rodent" pos="-0.000193459 -3.99858e-07 -0.000229687" axis="0 1 0"/>
          <geom name="vertebra_cervical_5_collision-rodent" class="no_collision-rodent" size="0.0081" type="sphere" density="300"/>
          <body name="vertebra_cervical_4-rodent" pos="0.00216814 -1.08135e-05 0.000728619">
            <joint name="vertebra_cervical_4_bend-rodent" class="cervical_bend-rodent" pos="-1.5376e-05 4.79726e-07 -0.000272791" axis="-0.318551 0 0.947906"/>
            <geom name="vertebra_cervical_4_collision-rodent" class="no_collision-rodent" size="0.00756" type="sphere" density="300"/>
            <body name="vertebra_cervical_3-rodent" pos="0.00193525 1.08734e-10 0.000847374">
              <joint name="vertebra_cervical_3_twist-rodent" class="cervical_twist-rodent" pos="8.19757e-06 -4.8659e-12 -0.000254429" axis="0.916035 5.14683e-08 0.401098"/>
              <geom name="vertebra_cervical_3_collision-rodent" class="no_collision-rodent" size="0.00702" type="sphere" density="300"/>
              <body name="vertebra_cervical_2-rodent" pos="0.00170996 1.15558e-10 0.000787286">
                <joint name="vertebra_cervical_2_extend-rodent" class="cervical_extend-rodent" pos="1.29516e-05 -5.79537e-12 -0.000253875" axis="0 1 0"/>
                <geom name="vertebra_cervical_2_collision-rodent" class="no_collision-rodent" size="0.00648" type="sphere" density="300"/>
                <body name="vertebra_cervical_1-rodent" pos="0.00159976 4.06991e-10 0.000841566">
                  <joint name="vertebra_cervical_1_bend-rodent" class="cervical_bend-rodent" pos="2.74698e-05 -2.21757e-11 -0.000263769" axis="-0.465567 0 0.885012"/>
                  <geom name="vertebra_cervical_1_collision-rodent" class="no_collision-rodent" size="0.00594" type="sphere" density="300"/>
                  <body name="vertebra_axis-rodent" pos="0.00169408 -1.58099e-06 0.00153527">
                    <joint name="vertebra_axis_twist-rodent" class="cervical_twist-rodent" pos="9.94393e-05 7.3323e-08 -0.000267624" axis="0.740985 -0.000691515 0.671522"/>
                    <geom name="vertebra_axis_collision-rodent" class="no_collision-rodent" size="0.0054" type="sphere" density="300"/>
                    <body name="vertebra_atlant-rodent" pos="0.00220696 1.58129e-06 0.0012326">
                      <joint name="vertebra_atlant_extend-rodent" class="cervical_extend-rodent" pos="2.74058e-05 -4.95538e-08 -0.000211529" axis="0 1 0"/>
                      <geom name="vertebra_atlant_collision-rodent" class="no_collision-rodent" size="0.00486" type="sphere" density="300"/>
                      <body name="skull-rodent" pos="0.0233596 3.78212e-09 0.00159346">
                        <joint name="atlas-rodent" class="atlas-rodent" pos="-0.0284358 0 0" axis="0 -1 0"/>
                        <geom name="skull_0_collision-rodent" class="no_collision-rodent" size="0.0198857 0.0150261 0.009" pos="-0.00815314 0 0.000738" quat="0.996195 0 0.0871557 0" type="ellipsoid" density="703.108"/>
                        <geom name="skull_0b_collision-rodent" class="no_collision-rodent" size="0.0198857 0.0150261 0.009" pos="-0.00815314 0 0.002952" quat="0.996195 0 0.0871557 0" type="ellipsoid" density="1.40622"/>
                        <geom name="skull_F_collision-rodent" class="no_collision-rodent" size="0.00646285 0.00801391 0.018" pos="0.013045 0 -0.000738" quat="0.573576 0 0.819152 0" type="ellipsoid" density="703.108"/>
                        <geom name="skull_Fb_collision-rodent" class="no_collision-rodent" size="0.00646285 0.00801391 0.018" pos="0.013045 0 0.001476" quat="0.573576 0 0.819152 0" type="ellipsoid" density="1.40622"/>
                        <geom name="skull_L_collision-rodent" class="no_collision-rodent" size="0.00646285 0.0120209 0.0126" pos="0.00489188 0.00410713 -0.000738" quat="0.573576 0 0.819152 0" type="ellipsoid" density="703.108"/>
                        <geom name="eye_L_collision-rodent" class="no_collision-rodent" size="0.0036" pos="0.000994285 0.01152 0.00225" type="sphere" group="1" rgba="0 0 0 1"/>
                        <geom name="skull_R_collision-rodent" class="no_collision-rodent" size="0.00646285 0.0120209 0.0126" pos="0.00489188 -0.00410713 -0.000738" quat="0.573576 0 0.819152 0" type="ellipsoid" density="703.108"/>
                        <geom name="eye_R_collision-rodent" class="no_collision-rodent" size="0.0036" pos="0.000994285 -0.01152 0.00225" type="sphere" group="1" rgba="0 0 0 1"/>
                        <geom name="skull_P0_collision-rodent" class="no_collision-rodent" size="0.00596571 0.00560974 0.00144" pos="0.00163063 0 -0.005166" type="box" density="703.108"/>
                        <geom name="skull_P1_collision-rodent" class="no_collision-rodent" size="0.00397714 0.00360626 0.00108" pos="0.0057072 0 -0.005166" type="box" density="703.108"/>
                        <geom name="skull_P2_collision-rodent" class="no_collision-rodent" size="0.000994285 0.00300522 0.00072" pos="0.00774548 0 -0.005166" type="box" density="703.108"/>
                        <geom name="skull_T0_collision-rodent" class="no_collision-rodent" size="0.00497143 0.00601043 0.0036" pos="0.0269054 0 -0.005904" quat="0.965926 0 0.258819 0" type="ellipsoid" density="703.108"/>
                        <geom name="skull_T1_collision-rodent" class="no_collision-rodent" size="0.00198857 0.00150261 0.0063" pos="0.0252747 0.000821426 -0.01107" quat="0.965926 0 0.258819 0" type="ellipsoid" group="1" density="703.108" rgba="1 1 1 1"/>
                        <geom name="skull_T2_collision-rodent" class="no_collision-rodent" size="0.00198857 0.00150261 0.0063" pos="0.0252747 -0.000821426 -0.01107" quat="0.965926 0 0.258819 0" type="ellipsoid" group="1" density="703.108" rgba="1 1 1 1"/>
                        <site name="head-rodent" class="sensor-rodent" pos="0 0 0" size="0.002 0.002 0.002" type="box"/>
                        <camera name="egocentric-rodent" pos="0.01 0 0.005" quat="0.5 0.5 -0.5 -0.5" fovy="80"/>
                        <body name="jaw-rodent" pos="0.000407657 -1.42992e-08 -0.01476" quat="0.991445 0 0.130526 0">
                          <joint name="mandible-rodent" class="mandible-rodent" pos="-0.0185 0 0.004" axis="0 1 0" springref="-0.314159"/>
                          <geom name="jaw_back_collision-rodent" class="no_collision-rodent" size="0.0109371 0.0120209 0.0063" pos="-0.00978377 0 0.001845" quat="0.887011 0 0.461749 0" type="ellipsoid" density="314.057"/>
                          <geom name="jaw_F_collision-rodent" class="no_collision-rodent" size="0.00298286 0.00601043 0.0108" pos="0.00244594 0 -0.004428" quat="0.608761 0 0.793353 0" type="ellipsoid" density="314.057"/>
                          <geom name="jaw_L_collision-rodent" class="no_collision-rodent" size="0.00894857 0.00350609 0.0144" pos="-0.00489188 0.00739283 0.000738" quat="0.497636 0.0631841 0.845991 -0.180736" type="ellipsoid" density="314.057"/>
                          <geom name="jaw_R_collision-rodent" class="no_collision-rodent" size="0.00894857 0.00350609 0.0144" pos="-0.00489188 -0.00739283 0.000738" quat="0.497636 -0.0631841 0.845991 0.180736" type="ellipsoid" density="314.057"/>
                          <geom name="jaw_T0_collision-rodent" class="no_collision-rodent" size="0.00298286 0.00300522 0.0054" pos="0.0114144 0 -0.005166" quat="0.819152 0 0.573576 0" type="ellipsoid" density="314.057"/>
                          <geom name="jaw_T1_collision-rodent" class="no_collision-rodent" size="0.00198857 0.00120209 0.0063" pos="0.015491 0.000821426 -0.00369" quat="0.843391 0 0.5373 0" type="ellipsoid" group="1" density="314.057" rgba="1 1 1 1"/>
                          <geom name="jaw_T2_collision-rodent" class="no_collision-rodent" size="0.00198857 0.00120209 0.0063" pos="0.015491 -0.000821426 -0.00369" quat="0.843391 0 0.5373 0" type="ellipsoid" group="1" density="314.057" rgba="1 1 1 1"/>
                          <geom name="jaw_P0_collision-rodent" class="no_collision-rodent" size="0.00596571 0.00560974 0.00144" pos="-0.00244594 0 0.000738" quat="0.887011 0 0.461749 0" type="box" density="314.057"/>
                          <geom name="jaw_P1_collision-rodent" class="no_collision-rodent" size="0.00397714 0.00440765 0.0009" pos="0 0 -0.0008856" quat="0.965926 0 0.258819 0" type="box" density="314.057"/>
                          <geom name="jaw_P2_collision-rodent" class="no_collision-rodent" size="0.00397714 0.00360626 0.0009" pos="0.00244594 0 -0.0020664" quat="0.976296 0 0.21644 0" type="box" density="314.057"/>
                          <geom name="jaw_P3_collision-rodent" class="no_collision-rodent" size="0.00298286 0.00260452 0.00054" pos="0.00423963 0 -0.002583" quat="0.991445 0 0.130526 0" type="box" density="314.057"/>
                        </body>
                      </body>
                    </body>
                  </body>
                </body>
              </body>
            </body>
          </body>
        </body>
        <body name="scapula_L-rodent" pos="0.005904 0.001476 0.010332">
          <joint name="scapula_L_supinate-rodent" class="scapula_supinate-rodent" pos="0 -0.005 0" axis="0 0 1"/>
          <joint name="scapula_L_abduct-rodent" class="scapula_abduct-rodent" pos="0 -0.005 -0.01" axis="1 0 0"/>
          <joint name="scapula_L_extend-rodent" class="scapula_extend-rodent" pos="0 0 0" axis="0.287348 0.957826 0"/>
          <geom name="scapula_L_collision-rodent" class="no_collision-rodent" size="0.00450483 0.0131686 0.0218799" pos="0.0158136 0.00777323 -0.0137066" quat="0.184419 0.769222 0.474032 0.386756" type="ellipsoid" density="513.565"/>
          <site name="shoulder_L-rodent" pos="0.0287 0.00984 -0.02542" size="0.002" group="3" rgba="0 0 1 1"/>
          <body name="upper_arm_L-rodent" pos="0.02583 0.008856 -0.022878">
            <joint name="shoulder_L-rodent" class="shoulder-rodent" pos="0 0 0" axis="0 1 0"/>
            <joint name="shoulder_sup_L-rodent" class="shoulder_sup-rodent" pos="0 0 0" axis="0 0 -1"/>
            <geom name="humerus_L_collision-rodent" class="no_collision-rodent" size="0.00699419 0.0139884" pos="-0.00696901 0.00520918 -0.010785" quat="0.472561 0.345008 0.000701605 0.810959"/>
            <site name="elbow_L-rodent" pos="-0.0159312 0.0103553 -0.0223037" quat="0.773342 -0.633989 0 0" size="0.0006 0.004" group="3" type="cylinder" rgba="0 0 1 1"/>
            <body name="lower_arm_L-rodent" pos="-0.0143381 0.00931976 -0.0200733">
              <joint name="elbow_L-rodent" class="elbow-rodent" pos="0 0 0" axis="0 0.980581 0.196116"/>
              <geom name="radius_L_collision-rodent" class="no_collision-rodent" size="0.00335895 0.0143249" pos="0.0103549 0.00616566 -0.0110037" quat="0.0237649 0.791772 0.423229 0.439783"/>
              <geom name="ulna_L_collision-rodent" class="no_collision-rodent" size="0.0039517 0.0118551" pos="0.00607479 0.00449318 -0.00854086" quat="0.0128224 0.744625 0.477607 0.466113"/>
              <site name="wrist_L-rodent" pos="0.0216027 0.0126015 -0.0198024" quat="0.707107 -0.707107 0 0" size="0.0008 0.0034" group="3" type="cylinder" rgba="0 0 1 1"/>
              <body name="hand_L-rodent" pos="0.0194424 0.0113414 -0.0178222">
                <joint name="wrist_L-rodent" class="wrist-rodent" pos="0 0 0" axis="0.514496 -0.857493 0"/>
                <geom name="hand_L_collision-rodent" class="nonself_collision_primitive_paw-rodent" size="0.00582317 0.00332753 0.00199652" pos="0.00136429 0.000682143 -0.00409286" quat="0.842137 -0.134404 0.485524 0.192371" type="ellipsoid" density="2531.78"/>
                <site name="finger_L-rodent" pos="0.00303175 0.00151587 -0.0083373" quat="0.707107 -0.693375 -0.138675 0" size="0.0006 0.005" group="3" type="cylinder" rgba="0 0 1 1"/>
                <body name="finger_L-rodent" pos="0.00272857 0.00136429 -0.00750357">
                  <joint name="finger_L-rodent" class="finger-rodent" pos="0 0 0" axis="-0.447214 0.894427 0"/>
                  <geom name="finger_L0_collision-rodent" class="nonself_collision_primitive_paw-rodent" size="0.00166376 0.00291159" pos="0.00443393 -0.000682143 0" quat="0.560986 0.560986 -0.430459 -0.430459"/>
                  <geom name="finger_L1_collision-rodent" class="nonself_collision_primitive_paw-rodent" size="0.00166376 0.00332753" pos="0.00409286 0.00170536 0" quat="0.602908 0.602908 -0.369462 -0.369462"/>
                  <geom name="finger_L2_collision-rodent" class="nonself_collision_primitive_paw-rodent" size="0.00166376 0.00291159" pos="0.0023875 0.00341072 0" quat="0.627211 0.627211 -0.326506 -0.326506"/>
                  <site name="palm_L-rodent" class="sensor-rodent" pos="0.00492 0.00246 -0.00164" quat="0.970296 0 0 0.241922" size="0.004 0.004 0.002" type="box"/>
                </body>
              </body>
            </body>
          </body>
        </body>
        <body name="scapula_R-rodent" pos="0.005904 -0.001476 0.010332">
          <joint name="scapula_R_supinate-rodent" class="scapula_supinate-rodent" pos="0 0.005 0" axis="0 0 -1"/>
          <joint name="scapula_R_abduct-rodent" class="scapula_abduct-rodent" pos="0 0.005 -0.01" axis="-1 0 0"/>
          <joint name="scapula_R_extend-rodent" class="scapula_extend-rodent" pos="0 0 0" axis="-0.287348 0.957826 0"/>
          <geom name="scapula_R_collision-rodent" class="no_collision-rodent" size="0.00450483 0.0131686 0.0218799" pos="0.0158136 -0.00777357 -0.0137066" quat="0.386756 0.474032 0.769222 0.184419" type="ellipsoid" density="513.565"/>
          <site name="shoulder_R-rodent" pos="0.0287 -0.00984 -0.02542" size="0.002" group="3" rgba="0 0 1 1"/>
          <body name="upper_arm_R-rodent" pos="0.02583 -0.008856 -0.022878">
            <joint name="shoulder_R-rodent" class="shoulder-rodent" pos="0 0 0" axis="0 1 0"/>
            <joint name="shoulder_sup_R-rodent" class="shoulder_sup-rodent" pos="0 0 0" axis="0 0 1"/>
            <geom name="humerus_R_collision-rodent" class="no_collision-rodent" size="0.00699419 0.0139884" pos="-0.00696901 -0.00520951 -0.010785" quat="0.810959 0.000701395 0.345008 0.472561"/>
            <site name="elbow_R-rodent" pos="-0.0159312 -0.0103553 -0.0223037" quat="0.633989 -0.773342 0 0" size="0.0006 0.004" group="3" type="cylinder" rgba="0 0 1 1"/>
            <body name="lower_arm_R-rodent" pos="-0.0143381 -0.00931976 -0.0200733">
              <joint name="elbow_R-rodent" class="elbow-rodent" pos="0 0 0" axis="0 0.980581 -0.196116"/>
              <geom name="radius_R_collision-rodent" class="no_collision-rodent" size="0.00335895 0.0143249" pos="0.0103549 -0.00616606 -0.0110037" quat="0.439783 0.42323 0.791772 0.0237656"/>
              <geom name="ulna_R_collision-rodent" class="no_collision-rodent" size="0.0039517 0.0118551" pos="0.00607479 -0.00449357 -0.00854086" quat="0.466113 0.477607 0.744625 0.0128225"/>
              <site name="wrist_R-rodent" pos="0.0216027 -0.0126015 -0.0198024" quat="0.707107 -0.707107 0 0" size="0.0008 0.0034" group="3" type="cylinder" rgba="0 0 1 1"/>
              <body name="hand_R-rodent" pos="0.0194424 -0.0113414 -0.0178222">
                <joint name="wrist_R-rodent" class="wrist-rodent" pos="0 0 0" axis="-0.514496 -0.857493 0"/>
                <geom name="hand_R_collision-rodent" class="nonself_collision_primitive_paw-rodent" size="0.00582317 0.00332753 0.00199652" pos="0.00136429 -0.000682143 -0.00409286" quat="0.842137 0.134404 0.485524 -0.192371" type="ellipsoid" density="2531.78"/>
                <site name="finger_R-rodent" pos="0.00303175 -0.00151587 -0.0083373" quat="0.707107 -0.693375 0.138675 0" size="0.0006 0.005" group="3" type="cylinder" rgba="0 0 1 1"/>
                <body name="finger_R-rodent" pos="0.00272857 -0.00136429 -0.00750357">
                  <joint name="finger_R-rodent" class="finger-rodent" pos="0 0 0" axis="0.447214 0.894427 0"/>
                  <geom name="finger_R0_collision-rodent" class="nonself_collision_primitive_paw-rodent" size="0.00166376 0.00291159" pos="0.00443393 0.000682143 0" quat="0.560986 0.560986 0.430459 0.430459"/>
                  <geom name="finger_R1_collision-rodent" class="nonself_collision_primitive_paw-rodent" size="0.00166376 0.00332753" pos="0.00409286 -0.00170536 0" quat="0.602908 0.602908 0.369462 0.369462"/>
                  <geom name="finger_R2_collision-rodent" class="nonself_collision_primitive_paw-rodent" size="0.00166376 0.00291159" pos="0.0023875 -0.00341072 0" quat="0.627211 0.627211 0.326506 0.326506"/>
                  <site name="palm_R-rodent" class="sensor-rodent" pos="0.00492 -0.00246 -0.00164" quat="0.970296 0 0 -0.241922" size="0.004 0.004 0.002" type="box"/>
                </body>
              </body>
            </body>
          </body>
        </body>
      </body>
    </body>
  </worldbody>

  <contact>
    <exclude name="upper_arm_L:torso-rodent" body1="torso-rodent" body2="upper_arm_L-rodent"/>
    <exclude name="upper_arm_R:torso-rodent" body1="torso-rodent" body2="upper_arm_R-rodent"/>
    <exclude name="lower_leg_L:pelvis-rodent" body1="pelvis-rodent" body2="lower_leg_L-rodent"/>
    <exclude name="lower_leg_R:pelvis-rodent" body1="pelvis-rodent" body2="lower_leg_R-rodent"/>
    <exclude name="pelvis:vertebra_C2-rodent" body1="pelvis-rodent" body2="vertebra_C2-rodent"/>
    <exclude name="pelvis:vertebra_C3-rodent" body1="pelvis-rodent" body2="vertebra_C3-rodent"/>
    <exclude name="pelvis:vertebra_C4-rodent" body1="pelvis-rodent" body2="vertebra_C4-rodent"/>
    <exclude name="pelvis:vertebra_C5-rodent" body1="pelvis-rodent" body2="vertebra_C5-rodent"/>
    <exclude name="pelvis:vertebra_C6-rodent" body1="pelvis-rodent" body2="vertebra_C6-rodent"/>
    <exclude name="upper_leg_L:vertebra_C1-rodent" body1="upper_leg_L-rodent" body2="vertebra_C1-rodent"/>
    <exclude name="upper_leg_L:vertebra_C2-rodent" body1="upper_leg_L-rodent" body2="vertebra_C2-rodent"/>
    <exclude name="upper_leg_R:vertebra_C1-rodent" body1="upper_leg_R-rodent" body2="vertebra_C1-rodent"/>
    <exclude name="upper_leg_R:vertebra_C2-rodent" body1="upper_leg_R-rodent" body2="vertebra_C2-rodent"/>
    <exclude name="vertebra_C1:vertebra_C3-rodent" body1="vertebra_C1-rodent" body2="vertebra_C3-rodent"/>
    <exclude name="vertebra_C1:vertebra_C4-rodent" body1="vertebra_C1-rodent" body2="vertebra_C4-rodent"/>
    <exclude name="vertebra_C2:vertebra_C4-rodent" body1="vertebra_C2-rodent" body2="vertebra_C4-rodent"/>
    <exclude name="vertebra_C2:vertebra_C5-rodent" body1="vertebra_C2-rodent" body2="vertebra_C5-rodent"/>
    <exclude name="vertebra_C3:vertebra_C5-rodent" body1="vertebra_C3-rodent" body2="vertebra_C5-rodent"/>
    <exclude name="vertebra_C3:vertebra_C6-rodent" body1="vertebra_C3-rodent" body2="vertebra_C6-rodent"/>
    <exclude name="vertebra_C4:vertebra_C6-rodent" body1="vertebra_C4-rodent" body2="vertebra_C6-rodent"/>
    <exclude name="vertebra_C4:vertebra_C7-rodent" body1="vertebra_C4-rodent" body2="vertebra_C7-rodent"/>
    <exclude name="vertebra_C5:vertebra_C7-rodent" body1="vertebra_C5-rodent" body2="vertebra_C7-rodent"/>
    <exclude name="vertebra_cervical_2:skull-rodent" body1="vertebra_cervical_2-rodent" body2="skull-rodent"/>
    <exclude name="vertebra_cervical_1:skull-rodent" body1="vertebra_cervical_1-rodent" body2="skull-rodent"/>
    <exclude name="vertebra_axis:skull-rodent" body1="vertebra_axis-rodent" body2="skull-rodent"/>
    <exclude name="upper_arm_L:upper_arm_R-rodent" body1="upper_arm_L-rodent" body2="upper_arm_R-rodent"/>
  </contact>

  <tendon>
    <fixed name="lumbar_extend-rodent" class="lumbar_extend-rodent">
      <joint joint="vertebra_1_extend-rodent" coef="0.604983"/>
      <joint joint="vertebra_4_extend-rodent" coef="0.395017"/>
    </fixed>
    <fixed name="lumbar_bend-rodent" class="lumbar_bend-rodent">
      <joint joint="vertebra_2_bend-rodent" coef="0.658212"/>
      <joint joint="vertebra_5_bend-rodent" coef="0.341788"/>
    </fixed>
    <fixed name="lumbar_twist-rodent" class="lumbar_twist-rodent">
      <joint joint="vertebra_3_twist-rodent" coef="0.57067"/>
      <joint joint="vertebra_6_twist-rodent" coef="0.42933"/>
    </fixed>
    <fixed name="cervical_extend-rodent" class="cervical_extend-rodent">
      <joint joint="vertebra_cervical_5_extend-rodent" coef="0.341714"/>
      <joint joint="vertebra_cervical_2_extend-rodent" coef="0.332408"/>
      <joint joint="vertebra_atlant_extend-rodent" coef="0.325878"/>
    </fixed>
    <fixed name="cervical_bend-rodent" class="cervical_bend-rodent">
      <joint joint="vertebra_cervical_4_bend-rodent" coef="0.507439"/>
      <joint joint="vertebra_cervical_1_bend-rodent" coef="0.492561"/>
    </fixed>
    <fixed name="cervical_twist-rodent" class="cervical_twist-rodent">
      <joint joint="vertebra_cervical_3_twist-rodent" coef="0.496142"/>
      <joint joint="vertebra_axis_twist-rodent" coef="0.503858"/>
    </fixed>
    <fixed name="caudal_extend-rodent" class="caudal_extend-rodent">
      <joint joint="vertebra_C1_extend-rodent" coef="0.290072"/>
      <joint joint="vertebra_C2_extend-rodent" coef="0.207669"/>
      <joint joint="vertebra_C3_extend-rodent" coef="0.151635"/>
      <joint joint="vertebra_C4_extend-rodent" coef="0.115427"/>
      <joint joint="vertebra_C5_extend-rodent" coef="0.0875498"/>
      <joint joint="vertebra_C6_extend-rodent" coef="0.0692563"/>
      <joint joint="vertebra_C7_extend-rodent" coef="0.0558692"/>
      <joint joint="vertebra_C11_extend-rodent" coef="0.0175307"/>
      <joint joint="vertebra_C15_extend-rodent" coef="0.00414417"/>
      <joint joint="vertebra_C19_extend-rodent" coef="0.000746423"/>
      <joint joint="vertebra_C23_extend-rodent" coef="8.59128e-05"/>
      <joint joint="vertebra_C27_extend-rodent" coef="1.42733e-05"/>
    </fixed>
    <fixed name="caudal_bend-rodent" class="caudal_bend-rodent">
      <joint joint="vertebra_C1_bend-rodent" coef="0.370793"/>
      <joint joint="vertebra_C2_bend-rodent" coef="0.233518"/>
      <joint joint="vertebra_C3_bend-rodent" coef="0.150894"/>
      <joint joint="vertebra_C4_bend-rodent" coef="0.101885"/>
      <joint joint="vertebra_C5_bend-rodent" coef="0.0671744"/>
      <joint joint="vertebra_C6_bend-rodent" coef="0.0439561"/>
      <joint joint="vertebra_C9_bend-rodent" coef="0.0188199"/>
      <joint joint="vertebra_C13_bend-rodent" coef="0.0099989"/>
      <joint joint="vertebra_C17_bend-rodent" coef="0.00252643"/>
      <joint joint="vertebra_C21_bend-rodent" coef="0.000378784"/>
      <joint joint="vertebra_C25_bend-rodent" coef="4.10657e-05"/>
      <joint joint="vertebra_C29_bend-rodent" coef="1.43866e-05"/>
    </fixed>
  </tendon>

  <actuator>
    <general name="lumbar_extend-rodent" tendon="lumbar_extend-rodent" ctrllimited="true" ctrlrange="-1 1" forcelimited="false" forcerange="-20 20" gear="0.81 0 0 0 0 0" dyntype="filter" dynprm="0.04 0 0 0 0 0 0 0 0 0" gainprm="20"/>
    <general name="lumbar_bend-rodent" tendon="lumbar_bend-rodent" ctrllimited="true" ctrlrange="-1 1" forcelimited="false" forcerange="-20 20" gear="0.81 0 0 0 0 0" dyntype="filter" dynprm="0.04 0 0 0 0 0 0 0 0 0" gainprm="20"/>
    <general name="lumbar_twist-rodent" tendon="lumbar_twist-rodent" ctrllimited="true" ctrlrange="-1 1" forcelimited="false" forcerange="-20 20" gear="0.81 0 0 0 0 0" dyntype="filter" dynprm="0.04 0 0 0 0 0 0 0 0 0" gainprm="20"/>
    <general name="cervical_extend-rodent" tendon="cervical_extend-rodent" ctrllimited="true" ctrlrange="-1 1" forcelimited="false" forcerange="-20 20" gear="0.81 0 0 0 0 0" dyntype="filter" dynprm="0.04 0 0 0 0 0 0 0 0 0" gainprm="20"/>
    <general name="cervical_bend-rodent" tendon="cervical_bend-rodent" ctrllimited="true" ctrlrange="-1 1" forcelimited="false" forcerange="-20 20" gear="0.81 0 0 0 0 0" dyntype="filter" dynprm="0.04 0 0 0 0 0 0 0 0 0" gainprm="20"/>
    <general name="cervical_twist-rodent" tendon="cervical_twist-rodent" ctrllimited="true" ctrlrange="-1 1" forcelimited="false" forcerange="-20 20" gear="0.81 0 0 0 0 0" dyntype="filter" dynprm="0.04 0 0 0 0 0 0 0 0 0" gainprm="20"/>
    <general name="caudal_extend-rodent" tendon="caudal_extend-rodent" ctrllimited="true" ctrlrange="-1 1" forcelimited="false" forcerange="-0.1 0.1" gear="0.81 0 0 0 0 0" dyntype="filter" dynprm="0.04 0 0 0 0 0 0 0 0 0" gainprm="0.1"/>
    <general name="caudal_bend-rodent" tendon="caudal_bend-rodent" ctrllimited="true" ctrlrange="-1 1" forcelimited="false" forcerange="-0.1 0.1" gear="0.81 0 0 0 0 0" dyntype="filter" dynprm="0.04 0 0 0 0 0 0 0 0 0" gainprm="0.1"/>
    <general name="hip_L_supinate-rodent" joint="hip_L_supinate-rodent" ctrllimited="true" ctrlrange="-1 1" forcelimited="false" forcerange="-0.2 0.2" gear="0.81 0 0 0 0 0" dyntype="filter" dynprm="0.04 0 0 0 0 0 0 0 0 0" gainprm="0.2"/>
    <general name="hip_L_abduct-rodent" joint="hip_L_abduct-rodent" ctrllimited="true" ctrlrange="-1 1" forcelimited="false" forcerange="-0.2 0.2" gear="0.81 0 0 0 0 0" dyntype="filter" dynprm="0.04 0 0 0 0 0 0 0 0 0" gainprm="0.2"/>
    <general name="hip_L_extend-rodent" joint="hip_L_extend-rodent" ctrllimited="true" ctrlrange="-1 1" forcelimited="false" forcerange="-0.3 0.3" gear="0.81 0 0 0 0 0" dyntype="filter" dynprm="0.04 0 0 0 0 0 0 0 0 0" gainprm="0.3"/>
    <general name="knee_L-rodent" joint="knee_L-rodent" ctrllimited="true" ctrlrange="-1 1" forcelimited="false" forcerange="-0.2 0.2" gear="0.81 0 0 0 0 0" dyntype="filter" dynprm="0.04 0 0 0 0 0 0 0 0 0" gainprm="0.2"/>
    <general name="ankle_L-rodent" joint="ankle_L-rodent" ctrllimited="true" ctrlrange="-1 1" forcelimited="false" forcerange="-0.2 0.2" gear="0.81 0 0 0 0 0" dyntype="filter" dynprm="0.04 0 0 0 0 0 0 0 0 0" gainprm="0.2"/>
    <general name="toe_L-rodent" joint="toe_L-rodent" ctrllimited="true" ctrlrange="-1 1" forcelimited="false" forcerange="-0.025 0.025" gear="0.81 0 0 0 0 0" dyntype="filter" dynprm="0.04 0 0 0 0 0 0 0 0 0" gainprm="0.025"/>
    <general name="hip_R_supinate-rodent" joint="hip_R_supinate-rodent" ctrllimited="true" ctrlrange="-1 1" forcelimited="false" forcerange="-0.2 0.2" gear="0.81 0 0 0 0 0" dyntype="filter" dynprm="0.04 0 0 0 0 0 0 0 0 0" gainprm="0.2"/>
    <general name="hip_R_abduct-rodent" joint="hip_R_abduct-rodent" ctrllimited="true" ctrlrange="-1 1" forcelimited="false" forcerange="-0.2 0.2" gear="0.81 0 0 0 0 0" dyntype="filter" dynprm="0.04 0 0 0 0 0 0 0 0 0" gainprm="0.2"/>
    <general name="hip_R_extend-rodent" joint="hip_R_extend-rodent" ctrllimited="true" ctrlrange="-1 1" forcelimited="false" forcerange="-0.3 0.3" gear="0.81 0 0 0 0 0" dyntype="filter" dynprm="0.04 0 0 0 0 0 0 0 0 0" gainprm="0.3"/>
    <general name="knee_R-rodent" joint="knee_R-rodent" ctrllimited="true" ctrlrange="-1 1" forcelimited="false" forcerange="-0.2 0.2" gear="0.81 0 0 0 0 0" dyntype="filter" dynprm="0.04 0 0 0 0 0 0 0 0 0" gainprm="0.2"/>
    <general name="ankle_R-rodent" joint="ankle_R-rodent" ctrllimited="true" ctrlrange="-1 1" forcelimited="false" forcerange="-0.2 0.2" gear="0.81 0 0 0 0 0" dyntype="filter" dynprm="0.04 0 0 0 0 0 0 0 0 0" gainprm="0.2"/>
    <general name="toe_R-rodent" joint="toe_R-rodent" ctrllimited="true" ctrlrange="-1 1" forcelimited="false" forcerange="-0.025 0.025" gear="0.81 0 0 0 0 0" dyntype="filter" dynprm="0.04 0 0 0 0 0 0 0 0 0" gainprm="0.025"/>
    <general name="atlas-rodent" joint="atlas-rodent" ctrllimited="true" ctrlrange="-1 1" forcelimited="false" forcerange="-0.025 0.025" gear="0.81 0 0 0 0 0" dyntype="filter" dynprm="0.04 0 0 0 0 0 0 0 0 0" gainprm="0.025"/>
    <general name="mandible-rodent" joint="mandible-rodent" ctrllimited="true" ctrlrange="-1 1" forcelimited="false" forcerange="-0.025 0.025" gear="0.81 0 0 0 0 0" dyntype="filter" dynprm="0.04 0 0 0 0 0 0 0 0 0" gainprm="0.025"/>
    <general name="scapula_L_supinate-rodent" joint="scapula_L_supinate-rodent" ctrllimited="true" ctrlrange="-1 1" forcelimited="false" forcerange="-0.25 0.25" gear="0.81 0 0 0 0 0" dyntype="filter" dynprm="0.04 0 0 0 0 0 0 0 0 0" gainprm="0.25"/>
    <general name="scapula_L_abduct-rodent" joint="scapula_L_abduct-rodent" ctrllimited="true" ctrlrange="-1 1" forcelimited="false" forcerange="-0.25 0.25" gear="0.81 0 0 0 0 0" dyntype="filter" dynprm="0.04 0 0 0 0 0 0 0 0 0" gainprm="0.25"/>
    <general name="scapula_L_extend-rodent" joint="scapula_L_extend-rodent" ctrllimited="true" ctrlrange="-1 1" forcelimited="false" forcerange="-0.25 0.25" gear="0.81 0 0 0 0 0" dyntype="filter" dynprm="0.04 0 0 0 0 0 0 0 0 0" gainprm="0.25"/>
    <general name="shoulder_L-rodent" joint="shoulder_L-rodent" ctrllimited="true" ctrlrange="-1 1" forcelimited="false" forcerange="-0.15 0.15" gear="0.81 0 0 0 0 0" dyntype="filter" dynprm="0.04 0 0 0 0 0 0 0 0 0" gainprm="0.15"/>
    <general name="shoulder_sup_L-rodent" joint="shoulder_sup_L-rodent" ctrllimited="true" ctrlrange="-1 1" forcelimited="false" forcerange="-0.15 0.15" gear="0.81 0 0 0 0 0" dyntype="filter" dynprm="0.04 0 0 0 0 0 0 0 0 0" gainprm="0.15"/>
    <general name="elbow_L-rodent" joint="elbow_L-rodent" ctrllimited="true" ctrlrange="-1 1" forcelimited="false" forcerange="-0.15 0.15" gear="0.81 0 0 0 0 0" dyntype="filter" dynprm="0.04 0 0 0 0 0 0 0 0 0" gainprm="0.15"/>
    <general name="wrist_L-rodent" joint="wrist_L-rodent" ctrllimited="true" ctrlrange="-1 1" forcelimited="false" forcerange="-0.05 0.05" gear="0.81 0 0 0 0 0" dyntype="filter" dynprm="0.04 0 0 0 0 0 0 0 0 0" gainprm="0.05"/>
    <general name="finger_L-rodent" joint="finger_L-rodent" ctrllimited="true" ctrlrange="-1 1" forcelimited="false" forcerange="-0.025 0.025" gear="0.81 0 0 0 0 0" dyntype="filter" dynprm="0.04 0 0 0 0 0 0 0 0 0" gainprm="0.025"/>
    <general name="scapula_R_supinate-rodent" joint="scapula_R_supinate-rodent" ctrllimited="true" ctrlrange="-1 1" forcelimited="false" forcerange="-0.25 0.25" gear="0.81 0 0 0 0 0" dyntype="filter" dynprm="0.04 0 0 0 0 0 0 0 0 0" gainprm="0.25"/>
    <general name="scapula_R_abduct-rodent" joint="scapula_R_abduct-rodent" ctrllimited="true" ctrlrange="-1 1" forcelimited="false" forcerange="-0.25 0.25" gear="0.81 0 0 0 0 0" dyntype="filter" dynprm="0.04 0 0 0 0 0 0 0 0 0" gainprm="0.25"/>
    <general name="scapula_R_extend-rodent" joint="scapula_R_extend-rodent" ctrllimited="true" ctrlrange="-1 1" forcelimited="false" forcerange="-0.25 0.25" gear="0.81 0 0 0 0 0" dyntype="filter" dynprm="0.04 0 0 0 0 0 0 0 0 0" gainprm="0.25"/>
    <general name="shoulder_R-rodent" joint="shoulder_R-rodent" ctrllimited="true" ctrlrange="-1 1" forcelimited="false" forcerange="-0.15 0.15" gear="0.81 0 0 0 0 0" dyntype="filter" dynprm="0.04 0 0 0 0 0 0 0 0 0" gainprm="0.15"/>
    <general name="shoulder_sup_R-rodent" joint="shoulder_sup_R-rodent" ctrllimited="true" ctrlrange="-1 1" forcelimited="false" forcerange="-0.15 0.15" gear="0.81 0 0 0 0 0" dyntype="filter" dynprm="0.04 0 0 0 0 0 0 0 0 0" gainprm="0.15"/>
    <general name="elbow_R-rodent" joint="elbow_R-rodent" ctrllimited="true" ctrlrange="-1 1" forcelimited="false" forcerange="-0.15 0.15" gear="0.81 0 0 0 0 0" dyntype="filter" dynprm="0.04 0 0 0 0 0 0 0 0 0" gainprm="0.15"/>
    <general name="wrist_R-rodent" joint="wrist_R-rodent" ctrllimited="true" ctrlrange="-1 1" forcelimited="false" forcerange="-0.05 0.05" gear="0.81 0 0 0 0 0" dyntype="filter" dynprm="0.04 0 0 0 0 0 0 0 0 0" gainprm="0.05"/>
    <general name="finger_R-rodent" joint="finger_R-rodent" ctrllimited="true" ctrlrange="-1 1" forcelimited="false" forcerange="-0.025 0.025" gear="0.81 0 0 0 0 0" dyntype="filter" dynprm="0.04 0 0 0 0 0 0 0 0 0" gainprm="0.025"/>
  </actuator>

  <sensor>
    <accelerometer site="head-rodent" name="accelerometer-rodent"/>
    <velocimeter site="head-rodent" name="velocimeter-rodent"/>
    <gyro site="head-rodent" name="gyro-rodent"/>
    <touch site="palm_L-rodent" name="palm_L-rodent"/>
    <touch site="palm_R-rodent" name="palm_R-rodent"/>
    <touch site="sole_L-rodent" name="sole_L-rodent"/>
    <touch site="sole_R-rodent" name="sole_R-rodent"/>
    <subtreelinvel body="torso-rodent" name="torso-rodent"/>
  </sensor>
</mujoco>
